Workbook

Sheet GERAL
A1: Panorama Geral das Unidades Escolares
A2: Atualizada em: 15/09/2026
A3: Escolas Novas Rui Costa | B3: Escolas Novas Gov. Jerônimo
A4: (*) - O nº de estudantes em processo de matricula estão sendo atualizados no sigeduc com série/turno, a planilha deverá ser regularizada até 30 de setembro/26.
A5: NTE | B5: MUNICIPIOS | C5: TIPO E - ESCOLA A - ANEXO EFA - ESCOLA AGRÍCOLA | D5: COD_SEC ESCOLA SEDE | E5: COD_SEC ANEXO | F5: COD_MEC | G5: COLÉGIO | H5: ENDEREÇO | I5: BAIRRO | J5: DISTANCIA PARA SEDE | K5: SITUAÇÃO DO PRÉDIO | L5: PORTE | T5: Nº DE SALAS (SIGDUC) | U5: Nº DE SALAS DE AULA VERDE: Atualizado pela nota em 2025 ROXO: Falta atualizar | V5: EDUCAÇÃO INFANTIL | AA5: FUNDAMENTAL | AF5: MÉDIO | AK5: EJA - FUND. | AO5: EJA - MÉDIO | AS5: PROFISSIONAL | AX5: TOTAL GERAL MATRICULADOS | AY5: TOTAL POR TURNO | BA5: Nº DE ESTUDANTES EM PROCESSO DE MATRICULA (*) | BB5: (*) TOTAL ESTUDANTES | BC5: MODALIDADE | BD5: CATEGORIA | BE5: ENSINO | BF5: OBS | BG5: cod sec ( para transferência dos dados) | BH5: Coordenadas Google Maps | BI5: N° de salas ( resumo) | BJ5: PADRÃO | BK5: MATRICULA INTEGRAL | BM5: POVOS
M6: DIRETOR(A) | N6: CELULAR | O6: VICE -DIRETOR(A) 1 | P6: CELULAR | Q6: VICE -DIRETOR(A) 2 | R6: CELULAR | S6: TELEFONE DA UEE | V6: MAT | W6: VES | X6: NOT | Y6: INTEG. | Z6: TOTAL | AA6: MAT | AB6: VES | AC6: NOT | AD6: INTEG. | AE6: TOTAL | AF6: MAT | AG6: VES | AH6: NOT | AI6: INTEGR. | AJ6: TOTAL | AK6: MAT | AL6: VES | AM6: NOT | AN6: TOTAL | AO6: MAT | AP6: VES | AQ6: NOT | AR6: TOTAL | AS6: MAT | AT6: VES | AU6: NOT | AV6: INTEGR. | AW6: TOTAL | AY6: DIURNO | AZ6: NOTURNO
A8: NTE 01 - IRECÊ | B8: AMERICA DOURADA | C8: ESCOLA | D8: 1125747 | F8: 29057809 | G8: COLÉGIO ESTADUAL SÃO SEBASTIÃO | H8: RUA NESTOR BORGES - 100 | I8: CENTRO | J8: SEDE | K8: PRÓPRIO | L8: GRANDE | M8: =IFERROR(__xludf.DUMMYFUNCTION("(VLOOKUP(D8, IMPORTRANGE(""https://docs.google.com/spreadsheets/d/1MjHtlUikwobi2MaWJgy7tfLeBmhj1u-dRFRs_8GwSoA/edit#gid=0"",""Gestores Escolares!D7:J""),3,0))"),"AURIVAN OLIVEIRA DE SOUZA") -> AURIVAN OLIVEIRA DE SOUZA | N8: =IFERROR(__xludf.DUMMYFUNCTION("IFERROR(VLOOKUP(D8, IMPORTRANGE(""https://docs.google.com/spreadsheets/d/1MjHtlUikwobi2MaWJgy7tfLeBmhj1u-dRFRs_8GwSoA/edit#gid=0"",""Gestores Escolares!D7:J""),4,0),""VERIFICAR CÓD SEC"")"),"(74) 9 9922-7133") -> (74) 9 9922-7133 | O8: =IFERROR(__xludf.DUMMYFUNCTION("IFERROR(VLOOKUP(D8, IMPORTRANGE(""https://docs.google.com/spreadsheets/d/1MjHtlUikwobi2MaWJgy7tfLeBmhj1u-dRFRs_8GwSoA/edit#gid=0"",""Gestores Escolares!D7:J""),6,0),""VERIFICAR CÓD SEC"")"),"LUCAS BORGES DOS SANTOS") -> LUCAS BORGES DOS SANTOS | P8: =IFERROR(__xludf.DUMMYFUNCTION("IFERROR(VLOOKUP(D8, IMPORTRANGE(""https://docs.google.com/spreadsheets/d/1MjHtlUikwobi2MaWJgy7tfLeBmhj1u-dRFRs_8GwSoA/edit#gid=0"",""Gestores Escolares!D7:J""),7,0),""VERIFICAR CÓD SEC"")"),"(74) 9 9816-6696") -> (74) 9 9816-6696 | Q8: =IFERROR(__xludf.DUMMYFUNCTION("IFERROR(VLOOKUP(D8, IMPORTRANGE(""https://docs.google.com/spreadsheets/d/1MjHtlUikwobi2MaWJgy7tfLeBmhj1u-dRFRs_8GwSoA/edit#gid=0"",""Gestores Escolares!D7:m""),9,0),""VERIFICAR CÓD SEC"")"),"") | R8: =IFERROR(__xludf.DUMMYFUNCTION("IFERROR(VLOOKUP(D8, IMPORTRANGE(""https://docs.google.com/spreadsheets/d/1MjHtlUikwobi2MaWJgy7tfLeBmhj1u-dRFRs_8GwSoA/edit#gid=0"",""Gestores Escolares!D7:m""),10,0),""VERIFICAR CÓD SEC"")"),"") | T8: 8 | U8: 8 | V8: 0 | W8: 0 | X8: 0 | Y8: 0 | Z8: =SUM(V8:Y8) -> 0 | AA8: 0 | AB8: 0 | AC8: 0 | AD8: 0 | AE8: =SUM(AA8:AD8) -> 0 | AF8: 183 | AG8: 172 | AH8: 0 | AI8: 0 | AJ8: =SUM(AF8:AI8) -> 355 | AK8: 0 | AL8: 0 | AM8: 0 | AN8: =SUM(AK8:AM8) -> 0 | AO8: 0 | AP8: 0 | AQ8: 74 | AR8: =SUM(AO8:AQ8) -> 74 | AS8: 0 | AT8: 0 | AU8: 32 | AV8: 0 | AW8: =SUM(AS8:AV8) -> 32 | AX8: =SUM(AY8:AZ8) -> 461 | AY8: =SUM(AV8,AT8,AS8,AP8,AO8,AL8,AK8,AI8,AG8,AF8,AD8,AB8,AA8,Y8,W8,V8) -> 355 | AZ8: =SUM(AU8,AQ8,AM8,AH8,AC8,X8) -> 106 | BA8: 0 | BB8: =SUM(AX8+BA8) -> 461 | BC8: ESCOLA SEDE | BD8: A DEFINIR | BE8: A DEFINIR | BG8: 1125747 | BH8: -11.456445479476455, -41.43890636036543 | BI8: 8 | BJ8: PADRÃO ANTIGO | BK8: =Y8+AD8+AI8+AV8 -> 0 | BL8: =V8+W8+AA8+AB8+AF8+AG8+AK8+AL8+AO8+AP8+AS8+AT8 -> 355 | BM8: =IFERROR(__xludf.DUMMYFUNCTION("IFERROR(VLOOKUP(BG8,IMPORTRANGE(""https://docs.google.com/spreadsheets/d/1juPI-Fb8LD0YtltB2mlGEnp_R3UVu1t3wSFPzgCyHXE/edit?gid=0#gid=0"",""GERAL!A2:C""),3,0),""-"")"),"-") -> -
A9: NTE 01 - IRECÊ | B9: AMERICA DOURADA | C9: ESCOLA | D9: 1179795 | F9: 29488974 | G9: COLÉGIO ESTADUAL DE TEMPO INTEGRAL PROFESSORA NANCY DA ROCHA CARDOSO - DIST. DE SOARES | H9: ESTRADA BA 052 - 88188 - N S/N Bairro: CENTRO CEP: 44910-000 | I9: CENTRO | K9: PRÓPRIO | L9: GRANDE | M9: =IFERROR(__xludf.DUMMYFUNCTION("IFERROR(VLOOKUP(D9, IMPORTRANGE(""https://docs.google.com/spreadsheets/d/1MjHtlUikwobi2MaWJgy7tfLeBmhj1u-dRFRs_8GwSoA/edit#gid=0"",""Gestores Escolares!D7:J""),3,0),""VERIFICAR CÓD SEC"")"),"ARIVONE MARIA DA SILVA SANTOS ") -> ARIVONE MARIA DA SILVA SANTOS | N9: =IFERROR(__xludf.DUMMYFUNCTION("IFERROR(VLOOKUP(D9, IMPORTRANGE(""https://docs.google.com/spreadsheets/d/1MjHtlUikwobi2MaWJgy7tfLeBmhj1u-dRFRs_8GwSoA/edit#gid=0"",""Gestores Escolares!D7:J""),4,0),""VERIFICAR CÓD SEC"")"),"(74) 9 8836-0537/ 9 9925-8934 (ZAP)") -> (74) 9 8836-0537/ 9 9925-8934 (ZAP) | O9: =IFERROR(__xludf.DUMMYFUNCTION("IFERROR(VLOOKUP(D9, IMPORTRANGE(""https://docs.google.com/spreadsheets/d/1MjHtlUikwobi2MaWJgy7tfLeBmhj1u-dRFRs_8GwSoA/edit#gid=0"",""Gestores Escolares!D7:J""),6,0),""VERIFICAR CÓD SEC"")"),"RODRIGO SILVA DE OLIVEIRA") -> RODRIGO SILVA DE OLIVEIRA | P9: =IFERROR(__xludf.DUMMYFUNCTION("IFERROR(VLOOKUP(D9, IMPORTRANGE(""https://docs.google.com/spreadsheets/d/1MjHtlUikwobi2MaWJgy7tfLeBmhj1u-dRFRs_8GwSoA/edit#gid=0"",""Gestores Escolares!D7:J""),7,0),""VERIFICAR CÓD SEC"")"),"(74) 9 9996-0577") -> (74) 9 9996-0577 | Q9: =IFERROR(__xludf.DUMMYFUNCTION("IFERROR(VLOOKUP(D9, IMPORTRANGE(""https://docs.google.com/spreadsheets/d/1MjHtlUikwobi2MaWJgy7tfLeBmhj1u-dRFRs_8GwSoA/edit#gid=0"",""Gestores Escolares!D7:m""),9,0),""VERIFICAR CÓD SEC"")"),"") | R9: =IFERROR(__xludf.DUMMYFUNCTION("IFERROR(VLOOKUP(D9, IMPORTRANGE(""https://docs.google.com/spreadsheets/d/1MjHtlUikwobi2MaWJgy7tfLeBmhj1u-dRFRs_8GwSoA/edit#gid=0"",""Gestores Escolares!D7:m""),10,0),""VERIFICAR CÓD SEC"")"),"") | T9: 12 | U9: 12 | V9: 0 | W9: 0 | X9: 0 | Y9: 0 | Z9: =SUM(V9:Y9) -> 0 | AA9: 0 | AB9: 0 | AC9: 0 | AD9: 0 | AE9: =SUM(AA9:AD9) -> 0 | AF9: 104 | AG9: 0 | AH9: 0 | AI9: 211 | AJ9: =SUM(AF9:AI9) -> 315 | AK9: 0 | AL9: 0 | AM9: 0 | AN9: =SUM(AK9:AM9) -> 0 | AO9: 0 | AP9: 0 | AQ9: 58 | AR9: =SUM(AO9:AQ9) -> 58 | AS9: 0 | AT9: 0 | AU9: 0 | AV9: 0 | AW9: =SUM(AS9:AV9) -> 0 | AX9: =SUM(AY9:AZ9) -> 373 | AY9: =SUM(AV9,AT9,AS9,AP9,AO9,AL9,AK9,AI9,AG9,AF9,AD9,AB9,AA9,Y9,W9,V9) -> 315 | AZ9: =SUM(AU9,AQ9,AM9,AH9,AC9,X9) -> 58 | BA9: 0 | BB9: =SUM(AX9+BA9) -> 373 | BG9: 1179795 | BH9: -11.313835928826945, -41.47264134866215 | BI9: 12 | BJ9: NOVO PADRÃO (NOVA ESCOLA) | BK9: =Y9+AD9+AI9+AV9 -> 211 | BL9: =V9+W9+AA9+AB9+AF9+AG9+AK9+AL9+AO9+AP9+AS9+AT9 -> 104 | BM9: =IFERROR(__xludf.DUMMYFUNCTION("IFERROR(VLOOKUP(BG9,IMPORTRANGE(""https://docs.google.com/spreadsheets/d/1juPI-Fb8LD0YtltB2mlGEnp_R3UVu1t3wSFPzgCyHXE/edit?gid=0#gid=0"",""GERAL!A2:C""),3,0),""-"")"),"-") -> -
A10: NTE 01 - IRECÊ | B10: AMERICA DOURADA | C10: ANEXO | D10: 1179281 | E10: 1178787 | F10: 29459141 | G10: ANEXO - CEMIT - IRECÊ - DISTRITO DE BELO CAMPO | H10: DISTRITO DE BELO CAMPO - SN(00004) | I10: CENTRO | J10: 31KM | K10: CEDIDO | L10: PEQUENO | M10: =IFERROR(__xludf.DUMMYFUNCTION("IFERROR(VLOOKUP(D10, IMPORTRANGE(""https://docs.google.com/spreadsheets/d/1MjHtlUikwobi2MaWJgy7tfLeBmhj1u-dRFRs_8GwSoA/edit#gid=0"",""Gestores Escolares!D7:J""),3,0),""VERIFICAR CÓD SEC"")"),"MARCOS PAULO DA SILVA ALMEIDA") -> MARCOS PAULO DA SILVA ALMEIDA | N10: =IFERROR(__xludf.DUMMYFUNCTION("IFERROR(VLOOKUP(D10, IMPORTRANGE(""https://docs.google.com/spreadsheets/d/1MjHtlUikwobi2MaWJgy7tfLeBmhj1u-dRFRs_8GwSoA/edit#gid=0"",""Gestores Escolares!D7:J""),4,0),""VERIFICAR CÓD SEC"")"),"(74) 9 9998-8112") -> (74) 9 9998-8112 | O10: =IFERROR(__xludf.DUMMYFUNCTION("IFERROR(VLOOKUP(D10, IMPORTRANGE(""https://docs.google.com/spreadsheets/d/1MjHtlUikwobi2MaWJgy7tfLeBmhj1u-dRFRs_8GwSoA/edit#gid=0"",""Gestores Escolares!D7:J""),6,0),""VERIFICAR CÓD SEC"")"),"FERNANDA MIRANDA CAMPOS") -> FERNANDA MIRANDA CAMPOS | P10: =IFERROR(__xludf.DUMMYFUNCTION("IFERROR(VLOOKUP(D10, IMPORTRANGE(""https://docs.google.com/spreadsheets/d/1MjHtlUikwobi2MaWJgy7tfLeBmhj1u-dRFRs_8GwSoA/edit#gid=0"",""Gestores Escolares!D7:J""),7,0),""VERIFICAR CÓD SEC"")"),"(74) 9 9963-4717") -> (74) 9 9963-4717 | Q10: =IFERROR(__xludf.DUMMYFUNCTION("IFERROR(VLOOKUP(D10, IMPORTRANGE(""https://docs.google.com/spreadsheets/d/1MjHtlUikwobi2MaWJgy7tfLeBmhj1u-dRFRs_8GwSoA/edit#gid=0"",""Gestores Escolares!D7:m""),9,0),""VERIFICAR CÓD SEC"")"),"") | R10: =IFERROR(__xludf.DUMMYFUNCTION("IFERROR(VLOOKUP(D10, IMPORTRANGE(""https://docs.google.com/spreadsheets/d/1MjHtlUikwobi2MaWJgy7tfLeBmhj1u-dRFRs_8GwSoA/edit#gid=0"",""Gestores Escolares!D7:m""),10,0),""VERIFICAR CÓD SEC"")"),"") | T10: 3 | U10: 3 | V10: 0 | W10: 0 | X10: 0 | Y10: 0 | Z10: =SUM(V10:Y10) -> 0 | AA10: 0 | AB10: 0 | AC10: 0 | AD10: 0 | AE10: =SUM(AA10:AD10) -> 0 | AF10: 0 | AG10: 0 | AH10: 23 | AI10: 0 | AJ10: =SUM(AF10:AI10) -> 23 | AK10: 0 | AL10: 0 | AM10: 0 | AN10: =SUM(AK10:AM10) -> 0 | AO10: 0 | AP10: 0 | AQ10: 0 | AR10: =SUM(AO10:AQ10) -> 0 | AS10: 0 | AT10: 0 | AU10: 0 | AV10: 0 | AW10: =SUM(AS10:AV10) -> 0 | AX10: =SUM(AY10:AZ10) -> 23 | AY10: =SUM(AV10,AT10,AS10,AP10,AO10,AL10,AK10,AI10,AG10,AF10,AD10,AB10,AA10,Y10,W10,V10) -> 0 | AZ10: =SUM(AU10,AQ10,AM10,AH10,AC10,X10) -> 23 | BA10: 0 | BB10: =SUM(AX10+BA10) -> 23 | BC10: A DEFINIR | BD10: CEMIT | BE10: PROFISSIONAL | BG10: 1178787 | BI10: 3 | BJ10: PADRÃO ANTIGO | BK10: =Y10+AD10+AI10+AV10 -> 0 | BL10: =V10+W10+AA10+AB10+AF10+AG10+AK10+AL10+AO10+AP10+AS10+AT10 -> 0 | BM10: =IFERROR(__xludf.DUMMYFUNCTION("IFERROR(VLOOKUP(BG10,IMPORTRANGE(""https://docs.google.com/spreadsheets/d/1juPI-Fb8LD0YtltB2mlGEnp_R3UVu1t3wSFPzgCyHXE/edit?gid=0#gid=0"",""GERAL!A2:C""),3,0),""-"")"),"-") -> -
A11: NTE 01 - IRECÊ | B11: BARRA DO MENDES | C11: ESCOLA | D11: 1125925 | F11: 29058244 | G11: COLEGIO ESTADUAL DE TEMPO INTEGRAL EDIVALDO MACHADO BOAVENTURA | H11: RUA JURACY MAGALHÃES - S/N | I11: CENTRO | J11: SEDE | K11: PRÓPRIO | L11: MÉDIO | M11: =IFERROR(__xludf.DUMMYFUNCTION("IFERROR(VLOOKUP(D11, IMPORTRANGE(""https://docs.google.com/spreadsheets/d/1MjHtlUikwobi2MaWJgy7tfLeBmhj1u-dRFRs_8GwSoA/edit#gid=0"",""Gestores Escolares!D7:J""),3,0),""VERIFICAR CÓD SEC"")"),"ANTÔNIO FRANCISCO RODRIGUES DE FREITAS") -> ANTÔNIO FRANCISCO RODRIGUES DE FREITAS | N11: =IFERROR(__xludf.DUMMYFUNCTION("IFERROR(VLOOKUP(D11, IMPORTRANGE(""https://docs.google.com/spreadsheets/d/1MjHtlUikwobi2MaWJgy7tfLeBmhj1u-dRFRs_8GwSoA/edit#gid=0"",""Gestores Escolares!D7:J""),4,0),""VERIFICAR CÓD SEC"")"),"(74) 9 9924-5179") -> (74) 9 9924-5179 | O11: =IFERROR(__xludf.DUMMYFUNCTION("IFERROR(VLOOKUP(D11, IMPORTRANGE(""https://docs.google.com/spreadsheets/d/1MjHtlUikwobi2MaWJgy7tfLeBmhj1u-dRFRs_8GwSoA/edit#gid=0"",""Gestores Escolares!D7:J""),6,0),""VERIFICAR CÓD SEC"")"),"SHIRLEY MENDES BARRETO") -> SHIRLEY MENDES BARRETO | P11: =IFERROR(__xludf.DUMMYFUNCTION("IFERROR(VLOOKUP(D11, IMPORTRANGE(""https://docs.google.com/spreadsheets/d/1MjHtlUikwobi2MaWJgy7tfLeBmhj1u-dRFRs_8GwSoA/edit#gid=0"",""Gestores Escolares!D7:J""),7,0),""VERIFICAR CÓD SEC"")"),"(74) 9 9801-4575") -> (74) 9 9801-4575 | Q11: =IFERROR(__xludf.DUMMYFUNCTION("IFERROR(VLOOKUP(D11, IMPORTRANGE(""https://docs.google.com/spreadsheets/d/1MjHtlUikwobi2MaWJgy7tfLeBmhj1u-dRFRs_8GwSoA/edit#gid=0"",""Gestores Escolares!D7:m""),9,0),""VERIFICAR CÓD SEC"")"),"") | R11: =IFERROR(__xludf.DUMMYFUNCTION("IFERROR(VLOOKUP(D11, IMPORTRANGE(""https://docs.google.com/spreadsheets/d/1MjHtlUikwobi2MaWJgy7tfLeBmhj1u-dRFRs_8GwSoA/edit#gid=0"",""Gestores Escolares!D7:m""),10,0),""VERIFICAR CÓD SEC"")"),"") | T11: 6 | U11: 11 salas, sendo 08 salas de aula, e 03 adaptadas para Sala de AEE e salas de oficinas do Educa Mais. | V11: 0 | W11: 0 | X11: 0 | Y11: 0 | Z11: =SUM(V11:Y11) -> 0 | AA11: 0 | AB11: 0 | AC11: 0 | AD11: 0 | AE11: =SUM(AA11:AD11) -> 0 | AF11: 63 | AG11: 59 | AH11: 0 | AI11: 127 | AJ11: =SUM(AF11:AI11) -> 249 | AK11: 0 | AL11: 0 | AM11: 0 | AN11: =SUM(AK11:AM11) -> 0 | AO11: 0 | AP11: 0 | AQ11: 40 | AR11: =SUM(AO11:AQ11) -> 40 | AS11: 0 | AT11: 0 | AU11: 0 | AV11: 118 | AW11: =SUM(AS11:AV11) -> 118 | AX11: =SUM(AY11:AZ11) -> 407 | AY11: =SUM(AV11,AT11,AS11,AP11,AO11,AL11,AK11,AI11,AG11,AF11,AD11,AB11,AA11,Y11,W11,V11) -> 367 | AZ11: =SUM(AU11,AQ11,AM11,AH11,AC11,X11) -> 40 | BA11: 0 | BB11: =SUM(AX11+BA11) -> 407 | BC11: ESCOLA SEDE | BD11: A DEFINIR | BE11: A DEFINIR | BG11: 1125925 | BH11: -11.804665179549133, -42.058620844234696 | BI11: 6 | BJ11: NOVO PADRÃO (AMPLIAÇÃO COM MODERNIZAÇÃO) | BK11: =Y11+AD11+AI11+AV11 -> 245 | BL11: =V11+W11+AA11+AB11+AF11+AG11+AK11+AL11+AO11+AP11+AS11+AT11 -> 122 | BM11: =IFERROR(__xludf.DUMMYFUNCTION("IFERROR(VLOOKUP(BG11,IMPORTRANGE(""https://docs.google.com/spreadsheets/d/1juPI-Fb8LD0YtltB2mlGEnp_R3UVu1t3wSFPzgCyHXE/edit?gid=0#gid=0"",""GERAL!A2:C""),3,0),""-"")"),"-") -> -
A12: NTE 01 - IRECÊ | B12: BARRA DO MENDES | C12: ANEXO | D12: 1125925 | E12: 1178206 | F12: 29491916 | G12: ANEXO-COL EST DE T. INTEG EDIVALDO MACHADO BOAVENTURA-DIST DE CANARINA | H12: DISTRITO DE CANARINA - S/N | I12: CANARINA | J12: 60KM | K12: CEDIDO | L12: PEQUENO | M12: =IFERROR(__xludf.DUMMYFUNCTION("IFERROR(VLOOKUP(D12, IMPORTRANGE(""https://docs.google.com/spreadsheets/d/1MjHtlUikwobi2MaWJgy7tfLeBmhj1u-dRFRs_8GwSoA/edit#gid=0"",""Gestores Escolares!D7:J""),3,0),""VERIFICAR CÓD SEC"")"),"ANTÔNIO FRANCISCO RODRIGUES DE FREITAS") -> ANTÔNIO FRANCISCO RODRIGUES DE FREITAS | N12: =IFERROR(__xludf.DUMMYFUNCTION("IFERROR(VLOOKUP(D12, IMPORTRANGE(""https://docs.google.com/spreadsheets/d/1MjHtlUikwobi2MaWJgy7tfLeBmhj1u-dRFRs_8GwSoA/edit#gid=0"",""Gestores Escolares!D7:J""),4,0),""VERIFICAR CÓD SEC"")"),"(74) 9 9924-5179") -> (74) 9 9924-5179 | O12: =IFERROR(__xludf.DUMMYFUNCTION("IFERROR(VLOOKUP(D12, IMPORTRANGE(""https://docs.google.com/spreadsheets/d/1MjHtlUikwobi2MaWJgy7tfLeBmhj1u-dRFRs_8GwSoA/edit#gid=0"",""Gestores Escolares!D7:J""),6,0),""VERIFICAR CÓD SEC"")"),"SHIRLEY MENDES BARRETO") -> SHIRLEY MENDES BARRETO | P12: =IFERROR(__xludf.DUMMYFUNCTION("IFERROR(VLOOKUP(D12, IMPORTRANGE(""https://docs.google.com/spreadsheets/d/1MjHtlUikwobi2MaWJgy7tfLeBmhj1u-dRFRs_8GwSoA/edit#gid=0"",""Gestores Escolares!D7:J""),7,0),""VERIFICAR CÓD SEC"")"),"(74) 9 9801-4575") -> (74) 9 9801-4575 | Q12: =IFERROR(__xludf.DUMMYFUNCTION("IFERROR(VLOOKUP(D12, IMPORTRANGE(""https://docs.google.com/spreadsheets/d/1MjHtlUikwobi2MaWJgy7tfLeBmhj1u-dRFRs_8GwSoA/edit#gid=0"",""Gestores Escolares!D7:m""),9,0),""VERIFICAR CÓD SEC"")"),"") | R12: =IFERROR(__xludf.DUMMYFUNCTION("IFERROR(VLOOKUP(D12, IMPORTRANGE(""https://docs.google.com/spreadsheets/d/1MjHtlUikwobi2MaWJgy7tfLeBmhj1u-dRFRs_8GwSoA/edit#gid=0"",""Gestores Escolares!D7:m""),10,0),""VERIFICAR CÓD SEC"")"),"") | T12: 4 | U12: 4 | V12: 0 | W12: 0 | X12: 0 | Y12: 0 | Z12: =SUM(V12:Y12) -> 0 | AA12: 0 | AB12: 0 | AC12: 0 | AD12: 0 | AE12: =SUM(AA12:AD12) -> 0 | AF12: 73 | AG12: 0 | AH12: 0 | AI12: 0 | AJ12: =SUM(AF12:AI12) -> 73 | AK12: 0 | AL12: 0 | AM12: 0 | AN12: =SUM(AK12:AM12) -> 0 | AO12: 0 | AP12: 0 | AQ12: 0 | AR12: =SUM(AO12:AQ12) -> 0 | AS12: 0 | AT12: 0 | AU12: 0 | AV12: 0 | AW12: =SUM(AS12:AV12) -> 0 | AX12: =SUM(AY12:AZ12) -> 73 | AY12: =SUM(AV12,AT12,AS12,AP12,AO12,AL12,AK12,AI12,AG12,AF12,AD12,AB12,AA12,Y12,W12,V12) -> 73 | AZ12: =SUM(AU12,AQ12,AM12,AH12,AC12,X12) -> 0 | BA12: 0 | BB12: =SUM(AX12+BA12) -> 73 | BC12: QUILOMBOLA | BD12: A DEFINIR | BE12: A DEFINIR | BG12: 1178206 | BH12: -11.804665179549133, -42.058620844234696 | BI12: 4 | BJ12: PADRÃO ANTIGO | BK12: =Y12+AD12+AI12+AV12 -> 0 | BL12: =V12+W12+AA12+AB12+AF12+AG12+AK12+AL12+AO12+AP12+AS12+AT12 -> 73 | BM12: =IFERROR(__xludf.DUMMYFUNCTION("IFERROR(VLOOKUP(BG12,IMPORTRANGE(""https://docs.google.com/spreadsheets/d/1juPI-Fb8LD0YtltB2mlGEnp_R3UVu1t3wSFPzgCyHXE/edit?gid=0#gid=0"",""GERAL!A2:C""),3,0),""-"")"),"QUILOMBOLAS") -> QUILOMBOLAS
A13: NTE 01 - IRECÊ | B13: BARRA DO MENDES | C13: ANEXO | D13: 1179281 | E13: 1178790 | F13: 29459141 | G13: ANEXO - CEMIT - IRECÊ - DISTRITO DE MILAGRES | H13: DISTRITO DE MILAGRES - S/N | I13: DISTRITO DE MILAGRES | J13: 30KM | K13: CEDIDO | L13: PEQUENO | M13: =IFERROR(__xludf.DUMMYFUNCTION("IFERROR(VLOOKUP(D13, IMPORTRANGE(""https://docs.google.com/spreadsheets/d/1MjHtlUikwobi2MaWJgy7tfLeBmhj1u-dRFRs_8GwSoA/edit#gid=0"",""Gestores Escolares!D7:J""),3,0),""VERIFICAR CÓD SEC"")"),"MARCOS PAULO DA SILVA ALMEIDA") -> MARCOS PAULO DA SILVA ALMEIDA | N13: =IFERROR(__xludf.DUMMYFUNCTION("IFERROR(VLOOKUP(D13, IMPORTRANGE(""https://docs.google.com/spreadsheets/d/1MjHtlUikwobi2MaWJgy7tfLeBmhj1u-dRFRs_8GwSoA/edit#gid=0"",""Gestores Escolares!D7:J""),4,0),""VERIFICAR CÓD SEC"")"),"(74) 9 9998-8112") -> (74) 9 9998-8112 | O13: =IFERROR(__xludf.DUMMYFUNCTION("IFERROR(VLOOKUP(D13, IMPORTRANGE(""https://docs.google.com/spreadsheets/d/1MjHtlUikwobi2MaWJgy7tfLeBmhj1u-dRFRs_8GwSoA/edit#gid=0"",""Gestores Escolares!D7:J""),6,0),""VERIFICAR CÓD SEC"")"),"FERNANDA MIRANDA CAMPOS") -> FERNANDA MIRANDA CAMPOS | P13: =IFERROR(__xludf.DUMMYFUNCTION("IFERROR(VLOOKUP(D13, IMPORTRANGE(""https://docs.google.com/spreadsheets/d/1MjHtlUikwobi2MaWJgy7tfLeBmhj1u-dRFRs_8GwSoA/edit#gid=0"",""Gestores Escolares!D7:J""),7,0),""VERIFICAR CÓD SEC"")"),"(74) 9 9963-4717") -> (74) 9 9963-4717 | Q13: =IFERROR(__xludf.DUMMYFUNCTION("IFERROR(VLOOKUP(D13, IMPORTRANGE(""https://docs.google.com/spreadsheets/d/1MjHtlUikwobi2MaWJgy7tfLeBmhj1u-dRFRs_8GwSoA/edit#gid=0"",""Gestores Escolares!D7:m""),9,0),""VERIFICAR CÓD SEC"")"),"") | R13: =IFERROR(__xludf.DUMMYFUNCTION("IFERROR(VLOOKUP(D13, IMPORTRANGE(""https://docs.google.com/spreadsheets/d/1MjHtlUikwobi2MaWJgy7tfLeBmhj1u-dRFRs_8GwSoA/edit#gid=0"",""Gestores Escolares!D7:m""),10,0),""VERIFICAR CÓD SEC"")"),"") | T13: 2 | U13: 2 | V13: 0 | W13: 0 | X13: 0 | Y13: 0 | Z13: =SUM(V13:Y13) -> 0 | AA13: 0 | AB13: 0 | AC13: 0 | AD13: 0 | AE13: =SUM(AA13:AD13) -> 0 | AF13: 0 | AG13: 0 | AH13: 55 | AI13: 0 | AJ13: =SUM(AF13:AI13) -> 55 | AK13: 0 | AL13: 0 | AM13: 0 | AN13: =SUM(AK13:AM13) -> 0 | AO13: 0 | AP13: 0 | AQ13: 0 | AR13: =SUM(AO13:AQ13) -> 0 | AS13: 0 | AT13: 0 | AU13: 0 | AV13: 0 | AW13: =SUM(AS13:AV13) -> 0 | AX13: =SUM(AY13:AZ13) -> 55 | AY13: =SUM(AV13,AT13,AS13,AP13,AO13,AL13,AK13,AI13,AG13,AF13,AD13,AB13,AA13,Y13,W13,V13) -> 0 | AZ13: =SUM(AU13,AQ13,AM13,AH13,AC13,X13) -> 55 | BA13: 0 | BB13: =SUM(AX13+BA13) -> 55 | BC13: A DEFINIR | BD13: CEMIT | BE13: PROFISSIONAL | BG13: 1178790 | BI13: 2 | BJ13: PADRÃO ANTIGO | BK13: =Y13+AD13+AI13+AV13 -> 0 | BL13: =V13+W13+AA13+AB13+AF13+AG13+AK13+AL13+AO13+AP13+AS13+AT13 -> 0 | BM13: =IFERROR(__xludf.DUMMYFUNCTION("IFERROR(VLOOKUP(BG13,IMPORTRANGE(""https://docs.google.com/spreadsheets/d/1juPI-Fb8LD0YtltB2mlGEnp_R3UVu1t3wSFPzgCyHXE/edit?gid=0#gid=0"",""GERAL!A2:C""),3,0),""-"")"),"-") -> -
A14: NTE 01 - IRECÊ | B14: BARRA DO MENDES | C14: ANEXO | D14: 1179281 | E14: 1178789 | F14: 29459141 | G14: ANEXO - CEMIT - IRECÊ - DISTRITO DE CAPIM DURO | H14: DISTRITO DE CAPIM DURO - S/N | I14: DISTRITO DE CAPIM DURO | J14: 37KM | K14: CEDIDO | L14: PEQUENO | M14: =IFERROR(__xludf.DUMMYFUNCTION("IFERROR(VLOOKUP(D14, IMPORTRANGE(""https://docs.google.com/spreadsheets/d/1MjHtlUikwobi2MaWJgy7tfLeBmhj1u-dRFRs_8GwSoA/edit#gid=0"",""Gestores Escolares!D7:J""),3,0),""VERIFICAR CÓD SEC"")"),"MARCOS PAULO DA SILVA ALMEIDA") -> MARCOS PAULO DA SILVA ALMEIDA | N14: =IFERROR(__xludf.DUMMYFUNCTION("IFERROR(VLOOKUP(D14, IMPORTRANGE(""https://docs.google.com/spreadsheets/d/1MjHtlUikwobi2MaWJgy7tfLeBmhj1u-dRFRs_8GwSoA/edit#gid=0"",""Gestores Escolares!D7:J""),4,0),""VERIFICAR CÓD SEC"")"),"(74) 9 9998-8112") -> (74) 9 9998-8112 | O14: =IFERROR(__xludf.DUMMYFUNCTION("IFERROR(VLOOKUP(D14, IMPORTRANGE(""https://docs.google.com/spreadsheets/d/1MjHtlUikwobi2MaWJgy7tfLeBmhj1u-dRFRs_8GwSoA/edit#gid=0"",""Gestores Escolares!D7:J""),6,0),""VERIFICAR CÓD SEC"")"),"FERNANDA MIRANDA CAMPOS") -> FERNANDA MIRANDA CAMPOS | P14: =IFERROR(__xludf.DUMMYFUNCTION("IFERROR(VLOOKUP(D14, IMPORTRANGE(""https://docs.google.com/spreadsheets/d/1MjHtlUikwobi2MaWJgy7tfLeBmhj1u-dRFRs_8GwSoA/edit#gid=0"",""Gestores Escolares!D7:J""),7,0),""VERIFICAR CÓD SEC"")"),"(74) 9 9963-4717") -> (74) 9 9963-4717 | Q14: =IFERROR(__xludf.DUMMYFUNCTION("IFERROR(VLOOKUP(D14, IMPORTRANGE(""https://docs.google.com/spreadsheets/d/1MjHtlUikwobi2MaWJgy7tfLeBmhj1u-dRFRs_8GwSoA/edit#gid=0"",""Gestores Escolares!D7:m""),9,0),""VERIFICAR CÓD SEC"")"),"") | R14: =IFERROR(__xludf.DUMMYFUNCTION("IFERROR(VLOOKUP(D14, IMPORTRANGE(""https://docs.google.com/spreadsheets/d/1MjHtlUikwobi2MaWJgy7tfLeBmhj1u-dRFRs_8GwSoA/edit#gid=0"",""Gestores Escolares!D7:m""),10,0),""VERIFICAR CÓD SEC"")"),"") | T14: 4 | U14: 4 | V14: 0 | W14: 0 | X14: 0 | Y14: 0 | Z14: =SUM(V14:Y14) -> 0 | AA14: 0 | AB14: 0 | AC14: 0 | AD14: 0 | AE14: =SUM(AA14:AD14) -> 0 | AF14: 26 | AG14: 0 | AH14: 84 | AI14: 0 | AJ14: =SUM(AF14:AI14) -> 110 | AK14: 0 | AL14: 0 | AM14: 0 | AN14: =SUM(AK14:AM14) -> 0 | AO14: 0 | AP14: 0 | AQ14: 0 | AR14: =SUM(AO14:AQ14) -> 0 | AS14: 0 | AT14: 0 | AU14: 0 | AV14: 0 | AW14: =SUM(AS14:AV14) -> 0 | AX14: =SUM(AY14:AZ14) -> 110 | AY14: =SUM(AV14,AT14,AS14,AP14,AO14,AL14,AK14,AI14,AG14,AF14,AD14,AB14,AA14,Y14,W14,V14) -> 26 | AZ14: =SUM(AU14,AQ14,AM14,AH14,AC14,X14) -> 84 | BA14: 0 | BB14: =SUM(AX14+BA14) -> 110 | BC14: A DEFINIR | BD14: CEMIT | BE14: PROFISSIONAL | BG14: 1178789 | BI14: 4 | BJ14: PADRÃO ANTIGO | BK14: =Y14+AD14+AI14+AV14 -> 0 | BL14: =V14+W14+AA14+AB14+AF14+AG14+AK14+AL14+AO14+AP14+AS14+AT14 -> 26 | BM14: =IFERROR(__xludf.DUMMYFUNCTION("IFERROR(VLOOKUP(BG14,IMPORTRANGE(""https://docs.google.com/spreadsheets/d/1juPI-Fb8LD0YtltB2mlGEnp_R3UVu1t3wSFPzgCyHXE/edit?gid=0#gid=0"",""GERAL!A2:C""),3,0),""-"")"),"-") -> -
A15: NTE 01 - IRECÊ | B15: BARRO ALTO | C15: ESCOLA | D15: 1179833 | F15: 29496969 | G15: COLEGIO ESTADUAL DO CAMPO DE GAMELEIRA | H15: RUA SETE DE SETEMBRO, Nº S/N | I15: CENTRO | K15: PRÓPRIO | L15: PEQUENO | M15: =IFERROR(__xludf.DUMMYFUNCTION("IFERROR(VLOOKUP(D15, IMPORTRANGE(""https://docs.google.com/spreadsheets/d/1MjHtlUikwobi2MaWJgy7tfLeBmhj1u-dRFRs_8GwSoA/edit#gid=0"",""Gestores Escolares!D7:J""),3,0),""VERIFICAR CÓD SEC"")"),"JANIVALDA ROSA MIRANDA") -> JANIVALDA ROSA MIRANDA | N15: =IFERROR(__xludf.DUMMYFUNCTION("IFERROR(VLOOKUP(D15, IMPORTRANGE(""https://docs.google.com/spreadsheets/d/1MjHtlUikwobi2MaWJgy7tfLeBmhj1u-dRFRs_8GwSoA/edit#gid=0"",""Gestores Escolares!D7:J""),4,0),""VERIFICAR CÓD SEC"")"),"(74) 9 9806-9091") -> (74) 9 9806-9091 | O15: =IFERROR(__xludf.DUMMYFUNCTION("IFERROR(VLOOKUP(D15, IMPORTRANGE(""https://docs.google.com/spreadsheets/d/1MjHtlUikwobi2MaWJgy7tfLeBmhj1u-dRFRs_8GwSoA/edit#gid=0"",""Gestores Escolares!D7:J""),6,0),""VERIFICAR CÓD SEC"")"),"") | P15: =IFERROR(__xludf.DUMMYFUNCTION("IFERROR(VLOOKUP(D15, IMPORTRANGE(""https://docs.google.com/spreadsheets/d/1MjHtlUikwobi2MaWJgy7tfLeBmhj1u-dRFRs_8GwSoA/edit#gid=0"",""Gestores Escolares!D7:J""),7,0),""VERIFICAR CÓD SEC"")"),"") | Q15: =IFERROR(__xludf.DUMMYFUNCTION("IFERROR(VLOOKUP(D15, IMPORTRANGE(""https://docs.google.com/spreadsheets/d/1MjHtlUikwobi2MaWJgy7tfLeBmhj1u-dRFRs_8GwSoA/edit#gid=0"",""Gestores Escolares!D7:m""),9,0),""VERIFICAR CÓD SEC"")"),"") | R15: =IFERROR(__xludf.DUMMYFUNCTION("IFERROR(VLOOKUP(D15, IMPORTRANGE(""https://docs.google.com/spreadsheets/d/1MjHtlUikwobi2MaWJgy7tfLeBmhj1u-dRFRs_8GwSoA/edit#gid=0"",""Gestores Escolares!D7:m""),10,0),""VERIFICAR CÓD SEC"")"),"") | V15: 0 | W15: 0 | X15: 0 | Y15: 0 | Z15: =SUM(V15:Y15) -> 0 | AA15: 0 | AB15: 0 | AC15: 0 | AD15: 0 | AE15: =SUM(AA15:AD15) -> 0 | AF15: 59 | AG15: 121 | AH15: 0 | AI15: 0 | AJ15: =SUM(AF15:AI15) -> 180 | AK15: 0 | AL15: 0 | AM15: 0 | AN15: =SUM(AK15:AM15) -> 0 | AO15: 0 | AP15: 0 | AQ15: 54 | AR15: =SUM(AO15:AQ15) -> 54 | AS15: 0 | AT15: 0 | AU15: 21 | AV15: 0 | AW15: =SUM(AS15:AV15) -> 21 | AX15: =SUM(AY15:AZ15) -> 255 | AY15: =SUM(AV15,AT15,AS15,AP15,AO15,AL15,AK15,AI15,AG15,AF15,AD15,AB15,AA15,Y15,W15,V15) -> 180 | AZ15: =SUM(AU15,AQ15,AM15,AH15,AC15,X15) -> 75 | BA15: 0 | BB15: =SUM(AX15+BA15) -> 255 | BC15: A DEFINIR | BD15: A DEFINIR | BE15: A DEFINIR | BG15: 1179833 | BK15: =Y15+AD15+AI15+AV15 -> 0 | BL15: =V15+W15+AA15+AB15+AF15+AG15+AK15+AL15+AO15+AP15+AS15+AT15 -> 180 | BM15: =IFERROR(__xludf.DUMMYFUNCTION("IFERROR(VLOOKUP(BG15,IMPORTRANGE(""https://docs.google.com/spreadsheets/d/1juPI-Fb8LD0YtltB2mlGEnp_R3UVu1t3wSFPzgCyHXE/edit?gid=0#gid=0"",""GERAL!A2:C""),3,0),""-"")"),"CAMPO") -> CAMPO
A16: NTE 01 - IRECÊ | B16: BARRO ALTO | C16: ESCOLA | D16: 1126212 | F16: 29059380 | G16: COLEGIO ESTADUAL DE TEMPO INTEGRAL NECY NOVAIS | H16: PRACA DA BANDEIRA - 282 | I16: CENTRO | J16: SEDE | K16: PRÓPRIO | L16: MÉDIO | M16: =IFERROR(__xludf.DUMMYFUNCTION("IFERROR(VLOOKUP(D16, IMPORTRANGE(""https://docs.google.com/spreadsheets/d/1MjHtlUikwobi2MaWJgy7tfLeBmhj1u-dRFRs_8GwSoA/edit#gid=0"",""Gestores Escolares!D7:J""),3,0),""VERIFICAR CÓD SEC"")"),"ARMANDA ANDRADE BARRETO RAMOS") -> ARMANDA ANDRADE BARRETO RAMOS | N16: =IFERROR(__xludf.DUMMYFUNCTION("IFERROR(VLOOKUP(D16, IMPORTRANGE(""https://docs.google.com/spreadsheets/d/1MjHtlUikwobi2MaWJgy7tfLeBmhj1u-dRFRs_8GwSoA/edit#gid=0"",""Gestores Escolares!D7:J""),4,0),""VERIFICAR CÓD SEC"")"),"(74) 9 9936-0280") -> (74) 9 9936-0280 | O16: =IFERROR(__xludf.DUMMYFUNCTION("IFERROR(VLOOKUP(D16, IMPORTRANGE(""https://docs.google.com/spreadsheets/d/1MjHtlUikwobi2MaWJgy7tfLeBmhj1u-dRFRs_8GwSoA/edit#gid=0"",""Gestores Escolares!D7:J""),6,0),""VERIFICAR CÓD SEC"")")," RAMON ROCHA RIBEIRO") -> RAMON ROCHA RIBEIRO | P16: =IFERROR(__xludf.DUMMYFUNCTION("IFERROR(VLOOKUP(D16, IMPORTRANGE(""https://docs.google.com/spreadsheets/d/1MjHtlUikwobi2MaWJgy7tfLeBmhj1u-dRFRs_8GwSoA/edit#gid=0"",""Gestores Escolares!D7:J""),7,0),""VERIFICAR CÓD SEC"")"),"(74) 9 8114-6964") -> (74) 9 8114-6964 | Q16: =IFERROR(__xludf.DUMMYFUNCTION("IFERROR(VLOOKUP(D16, IMPORTRANGE(""https://docs.google.com/spreadsheets/d/1MjHtlUikwobi2MaWJgy7tfLeBmhj1u-dRFRs_8GwSoA/edit#gid=0"",""Gestores Escolares!D7:m""),9,0),""VERIFICAR CÓD SEC"")"),"") | R16: =IFERROR(__xludf.DUMMYFUNCTION("IFERROR(VLOOKUP(D16, IMPORTRANGE(""https://docs.google.com/spreadsheets/d/1MjHtlUikwobi2MaWJgy7tfLeBmhj1u-dRFRs_8GwSoA/edit#gid=0"",""Gestores Escolares!D7:m""),10,0),""VERIFICAR CÓD SEC"")"),"") | T16: 5 | U16: 06 salas, sendo 05 utilizadas para aula, 01 adaptada para biblioteca e sala de vídeo. | V16: 0 | W16: 0 | X16: 0 | Y16: 0 | Z16: =SUM(V16:Y16) -> 0 | AA16: 0 | AB16: 0 | AC16: 0 | AD16: 0 | AE16: =SUM(AA16:AD16) -> 0 | AF16: 133 | AG16: 123 | AH16: 0 | AI16: 0 | AJ16: =SUM(AF16:AI16) -> 256 | AK16: 0 | AL16: 0 | AM16: 0 | AN16: =SUM(AK16:AM16) -> 0 | AO16: 0 | AP16: 0 | AQ16: 0 | AR16: =SUM(AO16:AQ16) -> 0 | AS16: 31 | AT16: 24 | AU16: 26 | AV16: 0 | AW16: =SUM(AS16:AV16) -> 81 | AX16: =SUM(AY16:AZ16) -> 337 | AY16: =SUM(AV16,AT16,AS16,AP16,AO16,AL16,AK16,AI16,AG16,AF16,AD16,AB16,AA16,Y16,W16,V16) -> 311 | AZ16: =SUM(AU16,AQ16,AM16,AH16,AC16,X16) -> 26 | BA16: 0 | BB16: =SUM(AX16+BA16) -> 337 | BC16: A DEFINIR | BD16: A DEFINIR | BE16: A DEFINIR | BG16: 1126212 | BH16: -11.317796181873934, -39.85582524236693 | BI16: 5 | BJ16: PADRÃO ANTIGO | BK16: =Y16+AD16+AI16+AV16 -> 0 | BL16: =V16+W16+AA16+AB16+AF16+AG16+AK16+AL16+AO16+AP16+AS16+AT16 -> 311 | BM16: =IFERROR(__xludf.DUMMYFUNCTION("IFERROR(VLOOKUP(BG16,IMPORTRANGE(""https://docs.google.com/spreadsheets/d/1juPI-Fb8LD0YtltB2mlGEnp_R3UVu1t3wSFPzgCyHXE/edit?gid=0#gid=0"",""GERAL!A2:C""),3,0),""-"")"),"-") -> -
A17: NTE 01 - IRECÊ | B17: CAFARNAUM | C17: ESCOLA | D17: 1126247 | F17: 29060001 | G17: COLÉGIO ESTADUAL DE TEMPO INTEGRAL IMACULADA CONCEIÇÃO | H17: CIRILO TOME DA SILVA - SN(00028) | I17: CENTRO | J17: SEDE | K17: PRÓPRIO | L17: GRANDE | M17: =IFERROR(__xludf.DUMMYFUNCTION("IFERROR(VLOOKUP(D17, IMPORTRANGE(""https://docs.google.com/spreadsheets/d/1MjHtlUikwobi2MaWJgy7tfLeBmhj1u-dRFRs_8GwSoA/edit#gid=0"",""Gestores Escolares!D7:J""),3,0),""VERIFICAR CÓD SEC"")"),"CÍCERA MARIA PIRES") -> CÍCERA MARIA PIRES | N17: =IFERROR(__xludf.DUMMYFUNCTION("IFERROR(VLOOKUP(D17, IMPORTRANGE(""https://docs.google.com/spreadsheets/d/1MjHtlUikwobi2MaWJgy7tfLeBmhj1u-dRFRs_8GwSoA/edit#gid=0"",""Gestores Escolares!D7:J""),4,0),""VERIFICAR CÓD SEC"")"),"(62) 9 9607-3189") -> (62) 9 9607-3189 | O17: =IFERROR(__xludf.DUMMYFUNCTION("IFERROR(VLOOKUP(D17, IMPORTRANGE(""https://docs.google.com/spreadsheets/d/1MjHtlUikwobi2MaWJgy7tfLeBmhj1u-dRFRs_8GwSoA/edit#gid=0"",""Gestores Escolares!D7:J""),6,0),""VERIFICAR CÓD SEC"")"),"CEZAR LOPES DE SOUZA") -> CEZAR LOPES DE SOUZA | P17: =IFERROR(__xludf.DUMMYFUNCTION("IFERROR(VLOOKUP(D17, IMPORTRANGE(""https://docs.google.com/spreadsheets/d/1MjHtlUikwobi2MaWJgy7tfLeBmhj1u-dRFRs_8GwSoA/edit#gid=0"",""Gestores Escolares!D7:J""),7,0),""VERIFICAR CÓD SEC"")"),"(74) 9 9804-9765") -> (74) 9 9804-9765 | Q17: =IFERROR(__xludf.DUMMYFUNCTION("IFERROR(VLOOKUP(D17, IMPORTRANGE(""https://docs.google.com/spreadsheets/d/1MjHtlUikwobi2MaWJgy7tfLeBmhj1u-dRFRs_8GwSoA/edit#gid=0"",""Gestores Escolares!D7:m""),9,0),""VERIFICAR CÓD SEC"")"),"") | R17: =IFERROR(__xludf.DUMMYFUNCTION("IFERROR(VLOOKUP(D17, IMPORTRANGE(""https://docs.google.com/spreadsheets/d/1MjHtlUikwobi2MaWJgy7tfLeBmhj1u-dRFRs_8GwSoA/edit#gid=0"",""Gestores Escolares!D7:m""),10,0),""VERIFICAR CÓD SEC"")"),"") | T17: 9 | U17: 17 | V17: 0 | W17: 0 | X17: 0 | Y17: 0 | Z17: =SUM(V17:Y17) -> 0 | AA17: 0 | AB17: 0 | AC17: 0 | AD17: 0 | AE17: =SUM(AA17:AD17) -> 0 | AF17: 0 | AG17: 0 | AH17: 0 | AI17: 555 | AJ17: =SUM(AF17:AI17) -> 555 | AK17: 0 | AL17: 0 | AM17: 0 | AN17: =SUM(AK17:AM17) -> 0 | AO17: 0 | AP17: 0 | AQ17: 108 | AR17: =SUM(AO17:AQ17) -> 108 | AS17: 0 | AT17: 0 | AU17: 0 | AV17: 82 | AW17: =SUM(AS17:AV17) -> 82 | AX17: =SUM(AY17:AZ17) -> 745 | AY17: =SUM(AV17,AT17,AS17,AP17,AO17,AL17,AK17,AI17,AG17,AF17,AD17,AB17,AA17,Y17,W17,V17) -> 637 | AZ17: =SUM(AU17,AQ17,AM17,AH17,AC17,X17) -> 108 | BA17: 0 | BB17: =SUM(AX17+BA17) -> 745 | BC17: A DEFINIR | BD17: A DEFINIR | BE17: A DEFINIR | BG17: 1126247 | BH17: -11.689388913938808, -41.475732103318904 | BI17: 9 | BJ17: NOVO PADRÃO (NOVA ESCOLA) | BK17: =Y17+AD17+AI17+AV17 -> 637 | BL17: =V17+W17+AA17+AB17+AF17+AG17+AK17+AL17+AO17+AP17+AS17+AT17 -> 0 | BM17: =IFERROR(__xludf.DUMMYFUNCTION("IFERROR(VLOOKUP(BG17,IMPORTRANGE(""https://docs.google.com/spreadsheets/d/1juPI-Fb8LD0YtltB2mlGEnp_R3UVu1t3wSFPzgCyHXE/edit?gid=0#gid=0"",""GERAL!A2:C""),3,0),""-"")"),"-") -> -
A18: NTE 01 - IRECÊ | B18: CAFARNAUM | C18: ANEXO | D18: 1179281 | E18: 1178792 | F18: 29459141 | G18: ANEXO - CEMIT - IRECÊ - DISTRITO DE CANAL | H18: HELIO MARQUES BARRETO - SN(00006) | I18: DISTRITO DE CANAL | J18: 22KM | K18: PRÓPRIO | L18: PEQUENO | M18: =IFERROR(__xludf.DUMMYFUNCTION("IFERROR(VLOOKUP(D18, IMPORTRANGE(""https://docs.google.com/spreadsheets/d/1MjHtlUikwobi2MaWJgy7tfLeBmhj1u-dRFRs_8GwSoA/edit#gid=0"",""Gestores Escolares!D7:J""),3,0),""VERIFICAR CÓD SEC"")"),"MARCOS PAULO DA SILVA ALMEIDA") -> MARCOS PAULO DA SILVA ALMEIDA | N18: =IFERROR(__xludf.DUMMYFUNCTION("IFERROR(VLOOKUP(D18, IMPORTRANGE(""https://docs.google.com/spreadsheets/d/1MjHtlUikwobi2MaWJgy7tfLeBmhj1u-dRFRs_8GwSoA/edit#gid=0"",""Gestores Escolares!D7:J""),4,0),""VERIFICAR CÓD SEC"")"),"(74) 9 9998-8112") -> (74) 9 9998-8112 | O18: =IFERROR(__xludf.DUMMYFUNCTION("IFERROR(VLOOKUP(D18, IMPORTRANGE(""https://docs.google.com/spreadsheets/d/1MjHtlUikwobi2MaWJgy7tfLeBmhj1u-dRFRs_8GwSoA/edit#gid=0"",""Gestores Escolares!D7:J""),6,0),""VERIFICAR CÓD SEC"")"),"FERNANDA MIRANDA CAMPOS") -> FERNANDA MIRANDA CAMPOS | P18: =IFERROR(__xludf.DUMMYFUNCTION("IFERROR(VLOOKUP(D18, IMPORTRANGE(""https://docs.google.com/spreadsheets/d/1MjHtlUikwobi2MaWJgy7tfLeBmhj1u-dRFRs_8GwSoA/edit#gid=0"",""Gestores Escolares!D7:J""),7,0),""VERIFICAR CÓD SEC"")"),"(74) 9 9963-4717") -> (74) 9 9963-4717 | Q18: =IFERROR(__xludf.DUMMYFUNCTION("IFERROR(VLOOKUP(D18, IMPORTRANGE(""https://docs.google.com/spreadsheets/d/1MjHtlUikwobi2MaWJgy7tfLeBmhj1u-dRFRs_8GwSoA/edit#gid=0"",""Gestores Escolares!D7:m""),9,0),""VERIFICAR CÓD SEC"")"),"") | R18: =IFERROR(__xludf.DUMMYFUNCTION("IFERROR(VLOOKUP(D18, IMPORTRANGE(""https://docs.google.com/spreadsheets/d/1MjHtlUikwobi2MaWJgy7tfLeBmhj1u-dRFRs_8GwSoA/edit#gid=0"",""Gestores Escolares!D7:m""),10,0),""VERIFICAR CÓD SEC"")"),"") | T18: 3 | U18: 1 | V18: 0 | W18: 0 | X18: 0 | Y18: 0 | Z18: =SUM(V18:Y18) -> 0 | AA18: 0 | AB18: 0 | AC18: 0 | AD18: 0 | AE18: =SUM(AA18:AD18) -> 0 | AF18: 0 | AG18: 0 | AH18: 60 | AI18: 0 | AJ18: =SUM(AF18:AI18) -> 60 | AK18: 0 | AL18: 0 | AM18: 0 | AN18: =SUM(AK18:AM18) -> 0 | AO18: 0 | AP18: 0 | AQ18: 0 | AR18: =SUM(AO18:AQ18) -> 0 | AS18: 0 | AT18: 0 | AU18: 0 | AV18: 0 | AW18: =SUM(AS18:AV18) -> 0 | AX18: =SUM(AY18:AZ18) -> 60 | AY18: =SUM(AV18,AT18,AS18,AP18,AO18,AL18,AK18,AI18,AG18,AF18,AD18,AB18,AA18,Y18,W18,V18) -> 0 | AZ18: =SUM(AU18,AQ18,AM18,AH18,AC18,X18) -> 60 | BA18: 0 | BB18: =SUM(AX18+BA18) -> 60 | BC18: A DEFINIR | BD18: CEMIT | BE18: PROFISSIONAL | BG18: 1178792 | BI18: 3 | BJ18: PADRÃO ANTIGO | BK18: =Y18+AD18+AI18+AV18 -> 0 | BL18: =V18+W18+AA18+AB18+AF18+AG18+AK18+AL18+AO18+AP18+AS18+AT18 -> 0 | BM18: =IFERROR(__xludf.DUMMYFUNCTION("IFERROR(VLOOKUP(BG18,IMPORTRANGE(""https://docs.google.com/spreadsheets/d/1juPI-Fb8LD0YtltB2mlGEnp_R3UVu1t3wSFPzgCyHXE/edit?gid=0#gid=0"",""GERAL!A2:C""),3,0),""-"")"),"-") -> -
A19: NTE 01 - IRECÊ | B19: CANARANA | C19: ESCOLA | D19: 1163100 | F19: 29060214 | G19: COLÉGIO ESTADUAL JOSÉ RIBEIRO DE ARAUJO | H19: RUA 16 DE JULHO - 177 | I19: CENTRO | J19: SEDE | K19: PRÓPRIO | L19: GRANDE | M19: =IFERROR(__xludf.DUMMYFUNCTION("IFERROR(VLOOKUP(D19, IMPORTRANGE(""https://docs.google.com/spreadsheets/d/1MjHtlUikwobi2MaWJgy7tfLeBmhj1u-dRFRs_8GwSoA/edit#gid=0"",""Gestores Escolares!D7:J""),3,0),""VERIFICAR CÓD SEC"")"),"OSIAS CARDOSO PIMENTA") -> OSIAS CARDOSO PIMENTA | N19: =IFERROR(__xludf.DUMMYFUNCTION("IFERROR(VLOOKUP(D19, IMPORTRANGE(""https://docs.google.com/spreadsheets/d/1MjHtlUikwobi2MaWJgy7tfLeBmhj1u-dRFRs_8GwSoA/edit#gid=0"",""Gestores Escolares!D7:J""),4,0),""VERIFICAR CÓD SEC"")"),"(74) 9 9988-0421") -> (74) 9 9988-0421 | O19: =IFERROR(__xludf.DUMMYFUNCTION("IFERROR(VLOOKUP(D19, IMPORTRANGE(""https://docs.google.com/spreadsheets/d/1MjHtlUikwobi2MaWJgy7tfLeBmhj1u-dRFRs_8GwSoA/edit#gid=0"",""Gestores Escolares!D7:J""),6,0),""VERIFICAR CÓD SEC"")"),"MONICA ALMEIDA DA SILVA GONÇALVES") -> MONICA ALMEIDA DA SILVA GONÇALVES | P19: =IFERROR(__xludf.DUMMYFUNCTION("IFERROR(VLOOKUP(D19, IMPORTRANGE(""https://docs.google.com/spreadsheets/d/1MjHtlUikwobi2MaWJgy7tfLeBmhj1u-dRFRs_8GwSoA/edit#gid=0"",""Gestores Escolares!D7:J""),7,0),""VERIFICAR CÓD SEC"")"),"(74) 9 9973-3834") -> (74) 9 9973-3834 | Q19: =IFERROR(__xludf.DUMMYFUNCTION("IFERROR(VLOOKUP(D19, IMPORTRANGE(""https://docs.google.com/spreadsheets/d/1MjHtlUikwobi2MaWJgy7tfLeBmhj1u-dRFRs_8GwSoA/edit#gid=0"",""Gestores Escolares!D7:m""),9,0),""VERIFICAR CÓD SEC"")"),"CALEBE MIRANDA DA SILVA") -> CALEBE MIRANDA DA SILVA | R19: =IFERROR(__xludf.DUMMYFUNCTION("IFERROR(VLOOKUP(D19, IMPORTRANGE(""https://docs.google.com/spreadsheets/d/1MjHtlUikwobi2MaWJgy7tfLeBmhj1u-dRFRs_8GwSoA/edit#gid=0"",""Gestores Escolares!D7:m""),10,0),""VERIFICAR CÓD SEC"")"),"(74) 9 9969-0595") -> (74) 9 9969-0595 | T19: 13 | U19: 10 + 03 (Adapt) | V19: 0 | W19: 0 | X19: 0 | Y19: 0 | Z19: =SUM(V19:Y19) -> 0 | AA19: 0 | AB19: 0 | AC19: 0 | AD19: 0 | AE19: =SUM(AA19:AD19) -> 0 | AF19: 0 | AG19: 0 | AH19: 0 | AI19: 489 | AJ19: =SUM(AF19:AI19) -> 489 | AK19: 0 | AL19: 0 | AM19: 0 | AN19: =SUM(AK19:AM19) -> 0 | AO19: 0 | AP19: 0 | AQ19: 0 | AR19: =SUM(AO19:AQ19) -> 0 | AS19: 0 | AT19: 0 | AU19: 98 | AV19: 0 | AW19: =SUM(AS19:AV19) -> 98 | AX19: =SUM(AY19:AZ19) -> 587 | AY19: =SUM(AV19,AT19,AS19,AP19,AO19,AL19,AK19,AI19,AG19,AF19,AD19,AB19,AA19,Y19,W19,V19) -> 489 | AZ19: =SUM(AU19,AQ19,AM19,AH19,AC19,X19) -> 98 | BA19: 0 | BB19: =SUM(AX19+BA19) -> 587 | BC19: A DEFINIR | BD19: A DEFINIR | BE19: A DEFINIR | BG19: 1163100 | BH19: -11.686352338828677, -41.769402236241454 | BI19: 10 | BJ19: PADRÃO ANTIGO | BK19: =Y19+AD19+AI19+AV19 -> 489 | BL19: =V19+W19+AA19+AB19+AF19+AG19+AK19+AL19+AO19+AP19+AS19+AT19 -> 0 | BM19: =IFERROR(__xludf.DUMMYFUNCTION("IFERROR(VLOOKUP(BG19,IMPORTRANGE(""https://docs.google.com/spreadsheets/d/1juPI-Fb8LD0YtltB2mlGEnp_R3UVu1t3wSFPzgCyHXE/edit?gid=0#gid=0"",""GERAL!A2:C""),3,0),""-"")"),"-") -> -
A20: NTE 01 - IRECÊ | B20: CANARANA | C20: ESCOLA | D20: 1137583 | F20: 29060206 | G20: COLÉGIO ESTADUAL DO CAMPO MAXIMINO MARTINS - DISTRITO DE SALOBRO | H20: PRAÇA CATÃO DOURADO - SN(00020) | I20: CENTRO | J20: 22KM | K20: PRÓPRIO | L20: MÉDIO | M20: =IFERROR(__xludf.DUMMYFUNCTION("IFERROR(VLOOKUP(D20, IMPORTRANGE(""https://docs.google.com/spreadsheets/d/1MjHtlUikwobi2MaWJgy7tfLeBmhj1u-dRFRs_8GwSoA/edit#gid=0"",""Gestores Escolares!D7:J""),3,0),""VERIFICAR CÓD SEC"")"),"LEDA DOURADO CARNEIRO MARTINS") -> LEDA DOURADO CARNEIRO MARTINS | N20: =IFERROR(__xludf.DUMMYFUNCTION("IFERROR(VLOOKUP(D20, IMPORTRANGE(""https://docs.google.com/spreadsheets/d/1MjHtlUikwobi2MaWJgy7tfLeBmhj1u-dRFRs_8GwSoA/edit#gid=0"",""Gestores Escolares!D7:J""),4,0),""VERIFICAR CÓD SEC"")"),"(74) 9 9996-9536") -> (74) 9 9996-9536 | O20: =IFERROR(__xludf.DUMMYFUNCTION("IFERROR(VLOOKUP(D20, IMPORTRANGE(""https://docs.google.com/spreadsheets/d/1MjHtlUikwobi2MaWJgy7tfLeBmhj1u-dRFRs_8GwSoA/edit#gid=0"",""Gestores Escolares!D7:J""),6,0),""VERIFICAR CÓD SEC"")"),"VAGNER NASCIMENTO MACHADO") -> VAGNER NASCIMENTO MACHADO | P20: =IFERROR(__xludf.DUMMYFUNCTION("IFERROR(VLOOKUP(D20, IMPORTRANGE(""https://docs.google.com/spreadsheets/d/1MjHtlUikwobi2MaWJgy7tfLeBmhj1u-dRFRs_8GwSoA/edit#gid=0"",""Gestores Escolares!D7:J""),7,0),""VERIFICAR CÓD SEC"")"),"(74) 9 9996-9006") -> (74) 9 9996-9006 | Q20: =IFERROR(__xludf.DUMMYFUNCTION("IFERROR(VLOOKUP(D20, IMPORTRANGE(""https://docs.google.com/spreadsheets/d/1MjHtlUikwobi2MaWJgy7tfLeBmhj1u-dRFRs_8GwSoA/edit#gid=0"",""Gestores Escolares!D7:m""),9,0),""VERIFICAR CÓD SEC"")"),"") | R20: =IFERROR(__xludf.DUMMYFUNCTION("IFERROR(VLOOKUP(D20, IMPORTRANGE(""https://docs.google.com/spreadsheets/d/1MjHtlUikwobi2MaWJgy7tfLeBmhj1u-dRFRs_8GwSoA/edit#gid=0"",""Gestores Escolares!D7:m""),10,0),""VERIFICAR CÓD SEC"")"),"") | T20: 8 | U20: 8 | V20: 0 | W20: 0 | X20: 0 | Y20: 0 | Z20: =SUM(V20:Y20) -> 0 | AA20: 0 | AB20: 0 | AC20: 0 | AD20: 0 | AE20: =SUM(AA20:AD20) -> 0 | AF20: 149 | AG20: 0 | AH20: 0 | AI20: 78 | AJ20: =SUM(AF20:AI20) -> 227 | AK20: 0 | AL20: 0 | AM20: 0 | AN20: =SUM(AK20:AM20) -> 0 | AO20: 0 | AP20: 0 | AQ20: 30 | AR20: =SUM(AO20:AQ20) -> 30 | AS20: 0 | AT20: 0 | AU20: 0 | AV20: 0 | AW20: =SUM(AS20:AV20) -> 0 | AX20: =SUM(AY20:AZ20) -> 257 | AY20: =SUM(AV20,AT20,AS20,AP20,AO20,AL20,AK20,AI20,AG20,AF20,AD20,AB20,AA20,Y20,W20,V20) -> 227 | AZ20: =SUM(AU20,AQ20,AM20,AH20,AC20,X20) -> 30 | BA20: 0 | BB20: =SUM(AX20+BA20) -> 257 | BC20: DO CAMPO | BD20: A DEFINIR | BE20: A DEFINIR | BG20: 1137583 | BH20: -11.859144622782148, -41.75367598550662 | BI20: 7 | BJ20: PADRÃO ANTIGO | BK20: =Y20+AD20+AI20+AV20 -> 78 | BL20: =V20+W20+AA20+AB20+AF20+AG20+AK20+AL20+AO20+AP20+AS20+AT20 -> 149 | BM20: =IFERROR(__xludf.DUMMYFUNCTION("IFERROR(VLOOKUP(BG20,IMPORTRANGE(""https://docs.google.com/spreadsheets/d/1juPI-Fb8LD0YtltB2mlGEnp_R3UVu1t3wSFPzgCyHXE/edit?gid=0#gid=0"",""GERAL!A2:C""),3,0),""-"")"),"CAMPO") -> CAMPO
A21: NTE 01 - IRECÊ | B21: CANARANA | C21: ANEXO | D21: 1179281 | E21: 1179207 | F21: 29459141 | G21: ANEXO - CEMIT - IRECÊ - POVOADO UMBURANA DO QUERE | H21: UMBURANA DO QUERE - SN(00006) | I21: POVOADO UMBURANA DO QUERE | J21: 35KM | K21: CEDIDO | L21: PEQUENO | M21: =IFERROR(__xludf.DUMMYFUNCTION("IFERROR(VLOOKUP(D21, IMPORTRANGE(""https://docs.google.com/spreadsheets/d/1MjHtlUikwobi2MaWJgy7tfLeBmhj1u-dRFRs_8GwSoA/edit#gid=0"",""Gestores Escolares!D7:J""),3,0),""VERIFICAR CÓD SEC"")"),"MARCOS PAULO DA SILVA ALMEIDA") -> MARCOS PAULO DA SILVA ALMEIDA | N21: =IFERROR(__xludf.DUMMYFUNCTION("IFERROR(VLOOKUP(D21, IMPORTRANGE(""https://docs.google.com/spreadsheets/d/1MjHtlUikwobi2MaWJgy7tfLeBmhj1u-dRFRs_8GwSoA/edit#gid=0"",""Gestores Escolares!D7:J""),4,0),""VERIFICAR CÓD SEC"")"),"(74) 9 9998-8112") -> (74) 9 9998-8112 | O21: =IFERROR(__xludf.DUMMYFUNCTION("IFERROR(VLOOKUP(D21, IMPORTRANGE(""https://docs.google.com/spreadsheets/d/1MjHtlUikwobi2MaWJgy7tfLeBmhj1u-dRFRs_8GwSoA/edit#gid=0"",""Gestores Escolares!D7:J""),6,0),""VERIFICAR CÓD SEC"")"),"FERNANDA MIRANDA CAMPOS") -> FERNANDA MIRANDA CAMPOS | P21: =IFERROR(__xludf.DUMMYFUNCTION("IFERROR(VLOOKUP(D21, IMPORTRANGE(""https://docs.google.com/spreadsheets/d/1MjHtlUikwobi2MaWJgy7tfLeBmhj1u-dRFRs_8GwSoA/edit#gid=0"",""Gestores Escolares!D7:J""),7,0),""VERIFICAR CÓD SEC"")"),"(74) 9 9963-4717") -> (74) 9 9963-4717 | Q21: =IFERROR(__xludf.DUMMYFUNCTION("IFERROR(VLOOKUP(D21, IMPORTRANGE(""https://docs.google.com/spreadsheets/d/1MjHtlUikwobi2MaWJgy7tfLeBmhj1u-dRFRs_8GwSoA/edit#gid=0"",""Gestores Escolares!D7:m""),9,0),""VERIFICAR CÓD SEC"")"),"") | R21: =IFERROR(__xludf.DUMMYFUNCTION("IFERROR(VLOOKUP(D21, IMPORTRANGE(""https://docs.google.com/spreadsheets/d/1MjHtlUikwobi2MaWJgy7tfLeBmhj1u-dRFRs_8GwSoA/edit#gid=0"",""Gestores Escolares!D7:m""),10,0),""VERIFICAR CÓD SEC"")"),"") | T21: 3 | U21: 3 | V21: 0 | W21: 0 | X21: 0 | Y21: 0 | Z21: =SUM(V21:Y21) -> 0 | AA21: 0 | AB21: 0 | AC21: 0 | AD21: 0 | AE21: =SUM(AA21:AD21) -> 0 | AF21: 0 | AG21: 0 | AH21: 64 | AI21: 0 | AJ21: =SUM(AF21:AI21) -> 64 | AK21: 0 | AL21: 0 | AM21: 0 | AN21: =SUM(AK21:AM21) -> 0 | AO21: 0 | AP21: 0 | AQ21: 0 | AR21: =SUM(AO21:AQ21) -> 0 | AS21: 0 | AT21: 0 | AU21: 0 | AV21: 0 | AW21: =SUM(AS21:AV21) -> 0 | AX21: =SUM(AY21:AZ21) -> 64 | AY21: =SUM(AV21,AT21,AS21,AP21,AO21,AL21,AK21,AI21,AG21,AF21,AD21,AB21,AA21,Y21,W21,V21) -> 0 | AZ21: =SUM(AU21,AQ21,AM21,AH21,AC21,X21) -> 64 | BA21: 0 | BB21: =SUM(AX21+BA21) -> 64 | BC21: A DEFINIR | BD21: CEMIT | BE21: PROFISSIONAL | BG21: 1179207 | BI21: 3 | BJ21: PADRÃO ANTIGO | BK21: =Y21+AD21+AI21+AV21 -> 0 | BL21: =V21+W21+AA21+AB21+AF21+AG21+AK21+AL21+AO21+AP21+AS21+AT21 -> 0 | BM21: =IFERROR(__xludf.DUMMYFUNCTION("IFERROR(VLOOKUP(BG21,IMPORTRANGE(""https://docs.google.com/spreadsheets/d/1juPI-Fb8LD0YtltB2mlGEnp_R3UVu1t3wSFPzgCyHXE/edit?gid=0#gid=0"",""GERAL!A2:C""),3,0),""-"")"),"-") -> -
A22: NTE 01 - IRECÊ | B22: CANARANA | C22: ANEXO | D22: 1179281 | E22: 1179160 | F22: 29459141 | G22: ANEXO - CEMIT - IRECÊ - DISTRITO LAGOA VELHA | H22: LAGOA VELHA - SN(00012) | I22: DISTRITO LAGOA VELHA | J22: 30KM | K22: CEDIDO | L22: PEQUENO | M22: =IFERROR(__xludf.DUMMYFUNCTION("IFERROR(VLOOKUP(D22, IMPORTRANGE(""https://docs.google.com/spreadsheets/d/1MjHtlUikwobi2MaWJgy7tfLeBmhj1u-dRFRs_8GwSoA/edit#gid=0"",""Gestores Escolares!D7:J""),3,0),""VERIFICAR CÓD SEC"")"),"MARCOS PAULO DA SILVA ALMEIDA") -> MARCOS PAULO DA SILVA ALMEIDA | N22: =IFERROR(__xludf.DUMMYFUNCTION("IFERROR(VLOOKUP(D22, IMPORTRANGE(""https://docs.google.com/spreadsheets/d/1MjHtlUikwobi2MaWJgy7tfLeBmhj1u-dRFRs_8GwSoA/edit#gid=0"",""Gestores Escolares!D7:J""),4,0),""VERIFICAR CÓD SEC"")"),"(74) 9 9998-8112") -> (74) 9 9998-8112 | O22: =IFERROR(__xludf.DUMMYFUNCTION("IFERROR(VLOOKUP(D22, IMPORTRANGE(""https://docs.google.com/spreadsheets/d/1MjHtlUikwobi2MaWJgy7tfLeBmhj1u-dRFRs_8GwSoA/edit#gid=0"",""Gestores Escolares!D7:J""),6,0),""VERIFICAR CÓD SEC"")"),"FERNANDA MIRANDA CAMPOS") -> FERNANDA MIRANDA CAMPOS | P22: =IFERROR(__xludf.DUMMYFUNCTION("IFERROR(VLOOKUP(D22, IMPORTRANGE(""https://docs.google.com/spreadsheets/d/1MjHtlUikwobi2MaWJgy7tfLeBmhj1u-dRFRs_8GwSoA/edit#gid=0"",""Gestores Escolares!D7:J""),7,0),""VERIFICAR CÓD SEC"")"),"(74) 9 9963-4717") -> (74) 9 9963-4717 | Q22: =IFERROR(__xludf.DUMMYFUNCTION("IFERROR(VLOOKUP(D22, IMPORTRANGE(""https://docs.google.com/spreadsheets/d/1MjHtlUikwobi2MaWJgy7tfLeBmhj1u-dRFRs_8GwSoA/edit#gid=0"",""Gestores Escolares!D7:m""),9,0),""VERIFICAR CÓD SEC"")"),"") | R22: =IFERROR(__xludf.DUMMYFUNCTION("IFERROR(VLOOKUP(D22, IMPORTRANGE(""https://docs.google.com/spreadsheets/d/1MjHtlUikwobi2MaWJgy7tfLeBmhj1u-dRFRs_8GwSoA/edit#gid=0"",""Gestores Escolares!D7:m""),10,0),""VERIFICAR CÓD SEC"")"),"") | T22: 3 | U22: 3 | V22: 0 | W22: 0 | X22: 0 | Y22: 0 | Z22: =SUM(V22:Y22) -> 0 | AA22: 0 | AB22: 0 | AC22: 0 | AD22: 0 | AE22: =SUM(AA22:AD22) -> 0 | AF22: 0 | AG22: 0 | AH22: 75 | AI22: 0 | AJ22: =SUM(AF22:AI22) -> 75 | AK22: 0 | AL22: 0 | AM22: 0 | AN22: =SUM(AK22:AM22) -> 0 | AO22: 0 | AP22: 0 | AQ22: 0 | AR22: =SUM(AO22:AQ22) -> 0 | AS22: 0 | AT22: 0 | AU22: 0 | AV22: 0 | AW22: =SUM(AS22:AV22) -> 0 | AX22: =SUM(AY22:AZ22) -> 75 | AY22: =SUM(AV22,AT22,AS22,AP22,AO22,AL22,AK22,AI22,AG22,AF22,AD22,AB22,AA22,Y22,W22,V22) -> 0 | AZ22: =SUM(AU22,AQ22,AM22,AH22,AC22,X22) -> 75 | BA22: 0 | BB22: =SUM(AX22+BA22) -> 75 | BC22: A DEFINIR | BD22: CEMIT | BE22: PROFISSIONAL | BG22: 1179160 | BI22: 3 | BJ22: PADRÃO ANTIGO | BK22: =Y22+AD22+AI22+AV22 -> 0 | BL22: =V22+W22+AA22+AB22+AF22+AG22+AK22+AL22+AO22+AP22+AS22+AT22 -> 0 | BM22: =IFERROR(__xludf.DUMMYFUNCTION("IFERROR(VLOOKUP(BG22,IMPORTRANGE(""https://docs.google.com/spreadsheets/d/1juPI-Fb8LD0YtltB2mlGEnp_R3UVu1t3wSFPzgCyHXE/edit?gid=0#gid=0"",""GERAL!A2:C""),3,0),""-"")"),"-") -> -
A23: NTE 01 - IRECÊ | B23: CENTRAL | C23: ESCOLA | D23: 1163088 | F23: 29061016 | G23: COLÉGIO ESTADUAL DE TEMPO INTEGRAL JOSE DE SOUZA MACHADO | H23: AV. ANTÔNIO CARLOS MAGALHÃES, 42 - CENTRO, CENTRAL - BA, 44940-000 | I23: CENTRO | J23: SEDE | K23: PRÓPRIO | L23: ESPECIAL | M23: =IFERROR(__xludf.DUMMYFUNCTION("IFERROR(VLOOKUP(D23, IMPORTRANGE(""https://docs.google.com/spreadsheets/d/1MjHtlUikwobi2MaWJgy7tfLeBmhj1u-dRFRs_8GwSoA/edit#gid=0"",""Gestores Escolares!D7:J""),3,0),""VERIFICAR CÓD SEC"")"),"TEREZA CRISTINA PORTO DE CARVALHO") -> TEREZA CRISTINA PORTO DE CARVALHO | N23: =IFERROR(__xludf.DUMMYFUNCTION("IFERROR(VLOOKUP(D23, IMPORTRANGE(""https://docs.google.com/spreadsheets/d/1MjHtlUikwobi2MaWJgy7tfLeBmhj1u-dRFRs_8GwSoA/edit#gid=0"",""Gestores Escolares!D7:J""),4,0),""VERIFICAR CÓD SEC"")"),"(77) 9 9940-7430/ 9 9813-4060") -> (77) 9 9940-7430/ 9 9813-4060 | O23: =IFERROR(__xludf.DUMMYFUNCTION("IFERROR(VLOOKUP(D23, IMPORTRANGE(""https://docs.google.com/spreadsheets/d/1MjHtlUikwobi2MaWJgy7tfLeBmhj1u-dRFRs_8GwSoA/edit#gid=0"",""Gestores Escolares!D7:J""),6,0),""VERIFICAR CÓD SEC"")"),"MARCIO SARMENTO AMARAL") -> MARCIO SARMENTO AMARAL | P23: =IFERROR(__xludf.DUMMYFUNCTION("IFERROR(VLOOKUP(D23, IMPORTRANGE(""https://docs.google.com/spreadsheets/d/1MjHtlUikwobi2MaWJgy7tfLeBmhj1u-dRFRs_8GwSoA/edit#gid=0"",""Gestores Escolares!D7:J""),7,0),""VERIFICAR CÓD SEC"")"),"(74) 9 9991-3155") -> (74) 9 9991-3155 | Q23: =IFERROR(__xludf.DUMMYFUNCTION("IFERROR(VLOOKUP(D23, IMPORTRANGE(""https://docs.google.com/spreadsheets/d/1MjHtlUikwobi2MaWJgy7tfLeBmhj1u-dRFRs_8GwSoA/edit#gid=0"",""Gestores Escolares!D7:m""),9,0),""VERIFICAR CÓD SEC"")")," REBECA CARVALHO DOS SANTOS") -> REBECA CARVALHO DOS SANTOS | R23: =IFERROR(__xludf.DUMMYFUNCTION("IFERROR(VLOOKUP(D23, IMPORTRANGE(""https://docs.google.com/spreadsheets/d/1MjHtlUikwobi2MaWJgy7tfLeBmhj1u-dRFRs_8GwSoA/edit#gid=0"",""Gestores Escolares!D7:m""),10,0),""VERIFICAR CÓD SEC"")"),"(74) 9 9943-0353") -> (74) 9 9943-0353 | T23: 10 | U23: 12 | V23: 0 | W23: 0 | X23: 0 | Y23: 0 | Z23: =SUM(V23:Y23) -> 0 | AA23: 0 | AB23: 0 | AC23: 0 | AD23: 0 | AE23: =SUM(AA23:AD23) -> 0 | AF23: 0 | AG23: 0 | AH23: 0 | AI23: 393 | AJ23: =SUM(AF23:AI23) -> 393 | AK23: 0 | AL23: 0 | AM23: 0 | AN23: =SUM(AK23:AM23) -> 0 | AO23: 0 | AP23: 0 | AQ23: 82 | AR23: =SUM(AO23:AQ23) -> 82 | AS23: 0 | AT23: 0 | AU23: 0 | AV23: 79 | AW23: =SUM(AS23:AV23) -> 79 | AX23: =SUM(AY23:AZ23) -> 554 | AY23: =SUM(AV23,AT23,AS23,AP23,AO23,AL23,AK23,AI23,AG23,AF23,AD23,AB23,AA23,Y23,W23,V23) -> 472 | AZ23: =SUM(AU23,AQ23,AM23,AH23,AC23,X23) -> 82 | BA23: 0 | BB23: =SUM(AX23+BA23) -> 554 | BC23: A DEFINIR | BD23: A DEFINIR | BE23: A DEFINIR | BG23: 1163088 | BH23: -11.131275357459675, -42.10954975054417 | BI23: 12 | BJ23: NOVO PADRÃO (NOVA ESCOLA) | BK23: =Y23+AD23+AI23+AV23 -> 472 | BL23: =V23+W23+AA23+AB23+AF23+AG23+AK23+AL23+AO23+AP23+AS23+AT23 -> 0 | BM23: =IFERROR(__xludf.DUMMYFUNCTION("IFERROR(VLOOKUP(BG23,IMPORTRANGE(""https://docs.google.com/spreadsheets/d/1juPI-Fb8LD0YtltB2mlGEnp_R3UVu1t3wSFPzgCyHXE/edit?gid=0#gid=0"",""GERAL!A2:C""),3,0),""-"")"),"-") -> -
A24: NTE 01 - IRECÊ | B24: GENTIO DO OURO | C24: ESCOLA | D24: 1125887 | F24: 29061628 | G24: COLÉGIO ESTADUAL MARIA QUITÉRIA - TEMPO INTEGRAL | H24: PÇA EDMUNDO PEREIRA BASTOS - 212 | I24: CENTRO | J24: SEDE | K24: PRÓPRIO | L24: GRANDE | M24: =IFERROR(__xludf.DUMMYFUNCTION("IFERROR(VLOOKUP(D24, IMPORTRANGE(""https://docs.google.com/spreadsheets/d/1MjHtlUikwobi2MaWJgy7tfLeBmhj1u-dRFRs_8GwSoA/edit#gid=0"",""Gestores Escolares!D7:J""),3,0),""VERIFICAR CÓD SEC"")"),"UMBERTO GOMES LEITE") -> UMBERTO GOMES LEITE | N24: =IFERROR(__xludf.DUMMYFUNCTION("IFERROR(VLOOKUP(D24, IMPORTRANGE(""https://docs.google.com/spreadsheets/d/1MjHtlUikwobi2MaWJgy7tfLeBmhj1u-dRFRs_8GwSoA/edit#gid=0"",""Gestores Escolares!D7:J""),4,0),""VERIFICAR CÓD SEC"")"),"(74) 9 8136-9548") -> (74) 9 8136-9548 | O24: =IFERROR(__xludf.DUMMYFUNCTION("IFERROR(VLOOKUP(D24, IMPORTRANGE(""https://docs.google.com/spreadsheets/d/1MjHtlUikwobi2MaWJgy7tfLeBmhj1u-dRFRs_8GwSoA/edit#gid=0"",""Gestores Escolares!D7:J""),6,0),""VERIFICAR CÓD SEC"")"),"ALESSANDRA DE SENA SILVA") -> ALESSANDRA DE SENA SILVA | P24: =IFERROR(__xludf.DUMMYFUNCTION("IFERROR(VLOOKUP(D24, IMPORTRANGE(""https://docs.google.com/spreadsheets/d/1MjHtlUikwobi2MaWJgy7tfLeBmhj1u-dRFRs_8GwSoA/edit#gid=0"",""Gestores Escolares!D7:J""),7,0),""VERIFICAR CÓD SEC"")"),"") | Q24: =IFERROR(__xludf.DUMMYFUNCTION("IFERROR(VLOOKUP(D24, IMPORTRANGE(""https://docs.google.com/spreadsheets/d/1MjHtlUikwobi2MaWJgy7tfLeBmhj1u-dRFRs_8GwSoA/edit#gid=0"",""Gestores Escolares!D7:m""),9,0),""VERIFICAR CÓD SEC"")"),"EDMILSON SOARES BARBOSA (COORDENADOR PEDAGÓGICO)") -> EDMILSON SOARES BARBOSA (COORDENADOR PEDAGÓGICO) | R24: =IFERROR(__xludf.DUMMYFUNCTION("IFERROR(VLOOKUP(D24, IMPORTRANGE(""https://docs.google.com/spreadsheets/d/1MjHtlUikwobi2MaWJgy7tfLeBmhj1u-dRFRs_8GwSoA/edit#gid=0"",""Gestores Escolares!D7:m""),10,0),""VERIFICAR CÓD SEC"")"),"(77) 9 9958-2972") -> (77) 9 9958-2972 | T24: 9 | U24: 7 | V24: 0 | W24: 0 | X24: 0 | Y24: 0 | Z24: =SUM(V24:Y24) -> 0 | AA24: 0 | AB24: 0 | AC24: 0 | AD24: 0 | AE24: =SUM(AA24:AD24) -> 0 | AF24: 0 | AG24: 0 | AH24: 0 | AI24: 141 | AJ24: =SUM(AF24:AI24) -> 141 | AK24: 0 | AL24: 0 | AM24: 0 | AN24: =SUM(AK24:AM24) -> 0 | AO24: 0 | AP24: 0 | AQ24: 19 | AR24: =SUM(AO24:AQ24) -> 19 | AS24: 0 | AT24: 0 | AU24: 14 | AV24: 99 | AW24: =SUM(AS24:AV24) -> 113 | AX24: =SUM(AY24:AZ24) -> 273 | AY24: =SUM(AV24,AT24,AS24,AP24,AO24,AL24,AK24,AI24,AG24,AF24,AD24,AB24,AA24,Y24,W24,V24) -> 240 | AZ24: =SUM(AU24,AQ24,AM24,AH24,AC24,X24) -> 33 | BA24: 0 | BB24: =SUM(AX24+BA24) -> 273 | BC24: A DEFINIR | BD24: A DEFINIR | BE24: A DEFINIR | BG24: 1125887 | BH24: -11.428866151079575, -42.50793797779119 | BI24: 7 | BJ24: PADRÃO ANTIGO | BK24: =Y24+AD24+AI24+AV24 -> 240 | BL24: =V24+W24+AA24+AB24+AF24+AG24+AK24+AL24+AO24+AP24+AS24+AT24 -> 0 | BM24: =IFERROR(__xludf.DUMMYFUNCTION("IFERROR(VLOOKUP(BG24,IMPORTRANGE(""https://docs.google.com/spreadsheets/d/1juPI-Fb8LD0YtltB2mlGEnp_R3UVu1t3wSFPzgCyHXE/edit?gid=0#gid=0"",""GERAL!A2:C""),3,0),""-"")"),"-") -> -
A25: NTE 01 - IRECÊ | B25: GENTIO DO OURO | C25: ANEXO | D25: 1125887 | E25: 1179258 | F25: 29492742 | G25: ANEXO - COLÉGIO ESTADUAL MARIA QUITÉRIA - DISTRITO DE ITAJUBAQUARA | H25: RUA EDMUNDO PEREIRA BASTOS - 212 | I25: CENTRO | J25: 18KM | K25: CEDIDO | L25: PEQUENO | M25: =IFERROR(__xludf.DUMMYFUNCTION("IFERROR(VLOOKUP(D25, IMPORTRANGE(""https://docs.google.com/spreadsheets/d/1MjHtlUikwobi2MaWJgy7tfLeBmhj1u-dRFRs_8GwSoA/edit#gid=0"",""Gestores Escolares!D7:J""),3,0),""VERIFICAR CÓD SEC"")"),"UMBERTO GOMES LEITE") -> UMBERTO GOMES LEITE | N25: =IFERROR(__xludf.DUMMYFUNCTION("IFERROR(VLOOKUP(D25, IMPORTRANGE(""https://docs.google.com/spreadsheets/d/1MjHtlUikwobi2MaWJgy7tfLeBmhj1u-dRFRs_8GwSoA/edit#gid=0"",""Gestores Escolares!D7:J""),4,0),""VERIFICAR CÓD SEC"")"),"(74) 9 8136-9548") -> (74) 9 8136-9548 | O25: =IFERROR(__xludf.DUMMYFUNCTION("IFERROR(VLOOKUP(D25, IMPORTRANGE(""https://docs.google.com/spreadsheets/d/1MjHtlUikwobi2MaWJgy7tfLeBmhj1u-dRFRs_8GwSoA/edit#gid=0"",""Gestores Escolares!D7:J""),6,0),""VERIFICAR CÓD SEC"")"),"ALESSANDRA DE SENA SILVA") -> ALESSANDRA DE SENA SILVA | P25: =IFERROR(__xludf.DUMMYFUNCTION("IFERROR(VLOOKUP(D25, IMPORTRANGE(""https://docs.google.com/spreadsheets/d/1MjHtlUikwobi2MaWJgy7tfLeBmhj1u-dRFRs_8GwSoA/edit#gid=0"",""Gestores Escolares!D7:J""),7,0),""VERIFICAR CÓD SEC"")"),"") | Q25: =IFERROR(__xludf.DUMMYFUNCTION("IFERROR(VLOOKUP(D25, IMPORTRANGE(""https://docs.google.com/spreadsheets/d/1MjHtlUikwobi2MaWJgy7tfLeBmhj1u-dRFRs_8GwSoA/edit#gid=0"",""Gestores Escolares!D7:m""),9,0),""VERIFICAR CÓD SEC"")"),"EDMILSON SOARES BARBOSA (COORDENADOR PEDAGÓGICO)") -> EDMILSON SOARES BARBOSA (COORDENADOR PEDAGÓGICO) | R25: =IFERROR(__xludf.DUMMYFUNCTION("IFERROR(VLOOKUP(D25, IMPORTRANGE(""https://docs.google.com/spreadsheets/d/1MjHtlUikwobi2MaWJgy7tfLeBmhj1u-dRFRs_8GwSoA/edit#gid=0"",""Gestores Escolares!D7:m""),10,0),""VERIFICAR CÓD SEC"")"),"(77) 9 9958-2972") -> (77) 9 9958-2972 | T25: 4 | U25: 2 | V25: 0 | W25: 0 | X25: 0 | Y25: 0 | Z25: =SUM(V25:Y25) -> 0 | AA25: 0 | AB25: 0 | AC25: 0 | AD25: 0 | AE25: =SUM(AA25:AD25) -> 0 | AF25: 0 | AG25: 0 | AH25: 0 | AI25: 0 | AJ25: =SUM(AF25:AI25) -> 0 | AK25: 0 | AL25: 0 | AM25: 0 | AN25: =SUM(AK25:AM25) -> 0 | AO25: 0 | AP25: 0 | AQ25: 47 | AR25: =SUM(AO25:AQ25) -> 47 | AS25: 0 | AT25: 0 | AU25: 0 | AV25: 0 | AW25: =SUM(AS25:AV25) -> 0 | AX25: =SUM(AY25:AZ25) -> 47 | AY25: =SUM(AV25,AT25,AS25,AP25,AO25,AL25,AK25,AI25,AG25,AF25,AD25,AB25,AA25,Y25,W25,V25) -> 0 | AZ25: =SUM(AU25,AQ25,AM25,AH25,AC25,X25) -> 47 | BA25: 0 | BB25: =SUM(AX25+BA25) -> 47 | BC25: DO CAMPO | BD25: A DEFINIR | BE25: A DEFINIR | BG25: 1179258 | BI25: 4 | BJ25: PADRÃO ANTIGO | BK25: =Y25+AD25+AI25+AV25 -> 0 | BL25: =V25+W25+AA25+AB25+AF25+AG25+AK25+AL25+AO25+AP25+AS25+AT25 -> 0 | BM25: =IFERROR(__xludf.DUMMYFUNCTION("IFERROR(VLOOKUP(BG25,IMPORTRANGE(""https://docs.google.com/spreadsheets/d/1juPI-Fb8LD0YtltB2mlGEnp_R3UVu1t3wSFPzgCyHXE/edit?gid=0#gid=0"",""GERAL!A2:C""),3,0),""-"")"),"CAMPO") -> CAMPO
A26: NTE 01 - IRECÊ | B26: GENTIO DO OURO | C26: ANEXO | D26: 1179281 | E26: 1178795 | F26: 29459141 | G26: ANEXO - CEMIT - IRECÊ- DISTRITO DE IBITUNANE | H26: DISTRITO DE IBITUNANE - S/N | I26: CENTRO | J26: 45KM | K26: CEDIDO | L26: PEQUENO | M26: =IFERROR(__xludf.DUMMYFUNCTION("IFERROR(VLOOKUP(D26, IMPORTRANGE(""https://docs.google.com/spreadsheets/d/1MjHtlUikwobi2MaWJgy7tfLeBmhj1u-dRFRs_8GwSoA/edit#gid=0"",""Gestores Escolares!D7:J""),3,0),""VERIFICAR CÓD SEC"")"),"MARCOS PAULO DA SILVA ALMEIDA") -> MARCOS PAULO DA SILVA ALMEIDA | N26: =IFERROR(__xludf.DUMMYFUNCTION("IFERROR(VLOOKUP(D26, IMPORTRANGE(""https://docs.google.com/spreadsheets/d/1MjHtlUikwobi2MaWJgy7tfLeBmhj1u-dRFRs_8GwSoA/edit#gid=0"",""Gestores Escolares!D7:J""),4,0),""VERIFICAR CÓD SEC"")"),"(74) 9 9998-8112") -> (74) 9 9998-8112 | O26: =IFERROR(__xludf.DUMMYFUNCTION("IFERROR(VLOOKUP(D26, IMPORTRANGE(""https://docs.google.com/spreadsheets/d/1MjHtlUikwobi2MaWJgy7tfLeBmhj1u-dRFRs_8GwSoA/edit#gid=0"",""Gestores Escolares!D7:J""),6,0),""VERIFICAR CÓD SEC"")"),"FERNANDA MIRANDA CAMPOS") -> FERNANDA MIRANDA CAMPOS | P26: =IFERROR(__xludf.DUMMYFUNCTION("IFERROR(VLOOKUP(D26, IMPORTRANGE(""https://docs.google.com/spreadsheets/d/1MjHtlUikwobi2MaWJgy7tfLeBmhj1u-dRFRs_8GwSoA/edit#gid=0"",""Gestores Escolares!D7:J""),7,0),""VERIFICAR CÓD SEC"")"),"(74) 9 9963-4717") -> (74) 9 9963-4717 | Q26: =IFERROR(__xludf.DUMMYFUNCTION("IFERROR(VLOOKUP(D26, IMPORTRANGE(""https://docs.google.com/spreadsheets/d/1MjHtlUikwobi2MaWJgy7tfLeBmhj1u-dRFRs_8GwSoA/edit#gid=0"",""Gestores Escolares!D7:m""),9,0),""VERIFICAR CÓD SEC"")"),"") | R26: =IFERROR(__xludf.DUMMYFUNCTION("IFERROR(VLOOKUP(D26, IMPORTRANGE(""https://docs.google.com/spreadsheets/d/1MjHtlUikwobi2MaWJgy7tfLeBmhj1u-dRFRs_8GwSoA/edit#gid=0"",""Gestores Escolares!D7:m""),10,0),""VERIFICAR CÓD SEC"")"),"") | T26: 3 | U26: 3 | V26: 0 | W26: 0 | X26: 0 | Y26: 0 | Z26: =SUM(V26:Y26) -> 0 | AA26: 0 | AB26: 0 | AC26: 0 | AD26: 0 | AE26: =SUM(AA26:AD26) -> 0 | AF26: 0 | AG26: 0 | AH26: 80 | AI26: 0 | AJ26: =SUM(AF26:AI26) -> 80 | AK26: 0 | AL26: 0 | AM26: 0 | AN26: =SUM(AK26:AM26) -> 0 | AO26: 0 | AP26: 0 | AQ26: 0 | AR26: =SUM(AO26:AQ26) -> 0 | AS26: 0 | AT26: 0 | AU26: 0 | AV26: 0 | AW26: =SUM(AS26:AV26) -> 0 | AX26: =SUM(AY26:AZ26) -> 80 | AY26: =SUM(AV26,AT26,AS26,AP26,AO26,AL26,AK26,AI26,AG26,AF26,AD26,AB26,AA26,Y26,W26,V26) -> 0 | AZ26: =SUM(AU26,AQ26,AM26,AH26,AC26,X26) -> 80 | BA26: 0 | BB26: =SUM(AX26+BA26) -> 80 | BC26: A DEFINIR | BD26: CEMIT | BE26: PROFISSIONAL | BG26: 1178795 | BI26: 3 | BJ26: PADRÃO ANTIGO | BK26: =Y26+AD26+AI26+AV26 -> 0 | BL26: =V26+W26+AA26+AB26+AF26+AG26+AK26+AL26+AO26+AP26+AS26+AT26 -> 0 | BM26: =IFERROR(__xludf.DUMMYFUNCTION("IFERROR(VLOOKUP(BG26,IMPORTRANGE(""https://docs.google.com/spreadsheets/d/1juPI-Fb8LD0YtltB2mlGEnp_R3UVu1t3wSFPzgCyHXE/edit?gid=0#gid=0"",""GERAL!A2:C""),3,0),""-"")"),"-") -> -
